Workbook

Sheet Client Info
A1: CALCULATIONS TOOL
A7: Quotation Tool for FlexMax Capital Appreciator Fixed Deposit Note 1 Year Term
A9: CLIENT NUMBER: | F9: OFDN-104-778-004
A11: CLIENT NAME: | F11: Marilyn Kannemeyer
A12: ADDRESS: | F12: 25 Kanna Road
F13: Belhar
F14: Western Cape
F15: 7493
F16: 0728882033
A18: OFFERED TO: | F18: =F11 -> Marilyn Kannemeyer
A19: INVESTMENT AMOUNT: | F19: 75000
A24: DATE OF CALCULATION: | F24: =TODAY() -> 46056
A25: COMMENCEMENT DATE OF PLAN | F25: 45962
A26: TERM IN YEARS | F26: 1
A27: REDEMPTION DATE | F27: 46326
A30: PREPARED BY: | F30: Lionel Lottering
F31: Cell: 076 309 2590
F32: Office: 0861 263 346
F33: Email: lionell@opianfsgroup.com

Sheet FDN_CapAPP_1-Year
B12: Quotation for FlexMax Capital Appreciator Fixed Deposit Note 1 Year Term
B14: Date of Offer: | E14: ='Client Info'!F24 -> 46056
B16: Offered to: | E16: ='Client Info'!F11 -> Marilyn Kannemeyer
B17: Adress: | E17: ='Client Info'!F12 -> 25 Kanna Road
E18: ='Client Info'!F13 -> Belhar
E19: {='Client Info'!F14:F14} -> Western Cape
E20: ='Client Info'!F15 -> 7493
B21: Telephone: | E21: ='Client Info'!F16 -> 0728882033
B22: Email:
B24: Dear | C24: ='Client Info'!F11 -> Marilyn Kannemeyer
B26: We take pleasure in submitting the following proposal to you:
B28: Investment summary
B29: Investment amount | K29: ='Client Info'!F19 -> 75000
B30: Amount allocated with enhancement | K30: =K29+'Client Info'!F21 -> 75000
B31: Term in years | K31: ='Client Info'!F26 -> 1
B32: Commencement date | K32: ='Client Info'!F25 -> 45962
B33: Percentage returned first year | K33: =I50 -> 0.0975
B34: Income allocated to capital in first year | K34: =J50 -> 7312.5
B35: Liquidity | K35: None
B37: Contract Start date | K37: ='Client Info'!F25 -> 45962
B38: Exit date | K38: ='Client Info'!F27 -> 46326
B39: Return Cycle | K39: Annually
B40: Capital allocation | K40: 1
B43: Registered Adress: 210 Amarand Avenue, Waterkloof Glen, 0181, Menlyn, Pretoria | H43: Fund Adress: Sovereign Trust International Limited.
B44: Email: info@opiancapital.com Website: www.opiancapital.com | H44: Sovereign Place, 117 Main Street, GX11 1AA, Gibraltar, GI
B46: Income projections
B47: Year | C47: Projection Scenarios
C48: Capital Value | I48: Return Forecast
C49: Current | I49: Projected | K49: Annualised
B50: 1 | C50: =K30 -> 75000 | I50: =Sheet1!D5 -> 0.0975 | J50: =C50*I50 -> 7312.5 | K50: =C50+J50 -> 82312.5
B54: Modelled Fund Choices
B55: ISIN | D55: Fund Name | H55: Type | J55: Split
B56: ISIN Code GG00B3TBCS61 | D56: WSF Global Equity Fund | H56: Risk-Adverse | J56: 1
B58: * | C58: Please note that fund choices will be modeled and should the dividends below these returns, the modeled returns will be payable to the client.
B60: Conditions:
B61: 1. To effectively evaluate this product against comparable alternatives, it is essential to analyze and contrast its risk and
B62: reward profile with those of similar products offering analogous risk-reward structures.
B64: 2. This offer involves the purchase of Fixed Deposit Notes FDN's in private equity. Given the inherent risks associated
B65: we strongly recommend independent advice before making any commitment.
B67: 3. This offer contains no guarantees beyond those expressly stated herein. Upon signing, the terms outlined in this offer
...

Sheet Sheet1
D2: YEARLY
D3: DIV
D4: ALLOCATION
B5: 1. | D5: 0.0975
